UndefinedError
jinja2.exceptions.UndefinedError: 'models.CompanySettings object' has no attribute 'get_financial_year'

Traceback (most recent call last)
File "/home/runner/AnaleeOriginal/.pythonlibs/lib/python3.11/site-packages/flask/app.py", line 1536, in __call__
return self.wsgi_app(environ, start_response)
       ^^^^^^^^^^^^^^^^^^^^^^^^^^^^^^^^^^^^^^
File "/home/runner/AnaleeOriginal/.pythonlibs/lib/python3.11/site-packages/flask/app.py", line 1514, in wsgi_app
response = self.handle_exception(e)
           ^^^^^^^^^^^^^^^^^^^^^^^^
File "/home/runner/AnaleeOriginal/.pythonlibs/lib/python3.11/site-packages/flask/app.py", line 1511, in wsgi_app
response = self.full_dispatch_request()
           ^^^^^^^^^^^^^^^^^^^^^^^^^^^^
File "/home/runner/AnaleeOriginal/.pythonlibs/lib/python3.11/site-packages/flask/app.py", line 919, in full_dispatch_request
rv = self.handle_user_exception(e)
     ^^^^^^^^^^^^^^^^^^^^^^^^^^^^^
File "/home/runner/AnaleeOriginal/.pythonlibs/lib/python3.11/site-packages/flask/app.py", line 917, in full_dispatch_request
rv = self.dispatch_request()
     ^^^^^^^^^^^^^^^^^^^^^^^
File "/home/runner/AnaleeOriginal/.pythonlibs/lib/python3.11/site-packages/flask/app.py", line 902, in dispatch_request
return self.ensure_sync(self.view_functions[rule.endpoint])(**view_args)  # type: ignore[no-any-return]
       ^^^^^^^^^^^^^^^^^^^^^^^^^^^^^^^^^^^^^^^^^^^^^^^^^^^^^^^^^^^^^^^^^
File "/home/runner/AnaleeOriginal/.pythonlibs/lib/python3.11/site-packages/flask_login/utils.py", line 290, in decorated_view
return current_app.ensure_sync(func)(*args, **kwargs)
       ^^^^^^^^^^^^^^^^^^^^^^^^^^^^^^^^^^^^^^^^^^^^^^
File "/home/runner/AnaleeOriginal/routes.py", line 293, in company_settings
return render_template(
       
File "/home/runner/AnaleeOriginal/.pythonlibs/lib/python3.11/site-packages/flask/templating.py", line 150, in render_template
return _render(app, template, context)
       ^^^^^^^^^^^^^^^^^^^^^^^^^^^^^^^
File "/home/runner/AnaleeOriginal/.pythonlibs/lib/python3.11/site-packages/flask/templating.py", line 131, in _render
rv = template.render(context)
     ^^^^^^^^^^^^^^^^^^^^^^^^
File "/home/runner/AnaleeOriginal/.pythonlibs/lib/python3.11/site-packages/jinja2/environment.py", line 1304, in render
self.environment.handle_exception()
^^^^^^^^^^^^^^^^^^^^^^^^^^^^^^^^^^^
File "/home/runner/AnaleeOriginal/.pythonlibs/lib/python3.11/site-packages/jinja2/environment.py", line 939, in handle_exception
raise rewrite_traceback_stack(source=source)
^^^^^^^^^^^^^^^^^^^^^^^^^^^^^^^^^^^^^^^^^^^^
File "/home/runner/AnaleeOriginal/templates/company_settings.html", line 1, in top-level template code
{% extends "base.html" %}
File "/home/runner/AnaleeOriginal/templates/base.html", line 91, in top-level template code
{% block content %}{% endblock %}
File "/home/runner/AnaleeOriginal/templates/company_settings.html", line 56, in block 'content'
{% set fy = settings.get_financial_year() %}
File "/home/runner/AnaleeOriginal/.pythonlibs/lib/python3.11/site-packages/jinja2/utils.py", line 83, in from_obj
if hasattr(obj, "jinja_pass_arg"):
   ^^^^^^^^^^^^^^^^^^^^^^^^^^^^^^
jinja2.exceptions.UndefinedError: 'models.CompanySettings object' has no attribute 'get_financial_year'
The debugger caught an exception in your WSGI application. You can now look at the traceback which led to the error.
To switch between the interactive traceback and the plaintext one, you can click on the "Traceback" headline. From the text traceback you can also create a paste of it.

Brought to you by DON'T PANIC, your friendly Werkzeug powered traceback interpreter.